Workbook

Sheet Executive Dashboard
A1: Mahindra & Mahindra Limited – Corporate Credit Risk Analysis
A2: Executive Dashboard | Consolidated unless stated | ₹ crore | Fiscal years end 31 March
A3: Disclaimer : This project is for educational and portfolio demonstration purposes only. It does not constitute an official credit assessment, lending decision, credit rating, or investment advice. Data Sources : Financial figures are sourced from publicly available company disclosures and credit-rating publications. Refer to the Source Register & Verification Log for source details and verification notes.
A4: Prepared by | B4: Tanmay Krishna Sattiraju
A5: Project title | B5: Corporate Credit Risk Analysis & AI-Assisted Decision Support
A6: Company analysed | B6: Mahindra & Mahindra Limited
A7: Classification | B7: Independent Educational Portfolio Project
A9: Select comparison year (drop-down): | B9: FY2026
A11: 1. Key credit indicators
A12: Indicator | B12: FY2024 | C12: FY2025 | D12: FY2026 | E12: Selected year | F12: Credit-favourable direction | G12: FY2026 vs FY2025 signal
A13: Revenue from operations (₹ crore) | B13: ='Financial Inputs'!$C$6 -> 139078.27 | C13: ='Financial Inputs'!$D$6 -> 159210.82 | D13: ='Financial Inputs'!$E$6 -> 197792.78 | E13: =INDEX(B13:D13,MATCH($B$9,$B$12:$D$12,0)) -> 197792.78 | F13: Higher | G13: =IF(AND(ISNUMBER(C13),ISNUMBER(D13)),IF(D13=C13,"No change",IF((D13>C13)=(F13="Higher"),"Favourable","Watch")),"n/a") -> Favourable
A14: Revenue growth (YoY) | B14: ='Financial Ratios'!C6 -> n/a | C14: ='Financial Ratios'!D6 -> 0.14475698 | D14: ='Financial Ratios'!E6 -> 0.24233252 | E14: =INDEX(B14:D14,MATCH($B$9,$B$12:$D$12,0)) -> 0.24233252 | F14: Higher | G14: =IF(AND(ISNUMBER(C14),ISNUMBER(D14)),IF(D14=C14,"No change",IF((D14>C14)=(F14="Higher"),"Favourable","Watch")),"n/a") -> Favourable
A15: PBT margin | B15: ='Financial Ratios'!C7 -> 0.11488344 | C15: ='Financial Ratios'!D7 -> 0.11983871 | D15: ='Financial Ratios'!E7 -> 0.12732902 | E15: =INDEX(B15:D15,MATCH($B$9,$B$12:$D$12,0)) -> 0.12732902 | F15: Higher | G15: =IF(AND(ISNUMBER(C15),ISNUMBER(D15)),IF(D15=C15,"No change",IF((D15>C15)=(F15="Higher"),"Favourable","Watch")),"n/a") -> Favourable
A16: Consolidated profit margin | B16: ='Financial Ratios'!C8 -> 0.088222409 | C16: ='Financial Ratios'!D8 -> 0.088393301 | D16: ='Financial Ratios'!E8 -> 0.094147572 | E16: =INDEX(B16:D16,MATCH($B$9,$B$12:$D$12,0)) -> 0.094147572 | F16: Higher | G16: =IF(AND(ISNUMBER(C16),ISNUMBER(D16)),IF(D16=C16,"No change",IF((D16>C16)=(F16="Higher"),"Favourable","Watch")),"n/a") -> Favourable
A17: Borrowings excl. leases (₹ crore) | B17: ='Financial Inputs'!$C$22 -> 103203.23 | C17: ='Financial Inputs'!$D$22 -> 121172.95 | D17: ='Financial Inputs'!$E$22 -> 129614.5 | E17: =INDEX(B17:D17,MATCH($B$9,$B$12:$D$12,0)) -> 129614.5 | F17: Lower | G17: =IF(AND(ISNUMBER(C17),ISNUMBER(D17)),IF(D17=C17,"No change",IF((D17>C17)=(F17="Higher"),"Favourable","Watch")),"n/a") -> Watch
A18: Current borrowings (₹ crore) | B18: ='Financial Inputs'!$C$21 -> 35483.54 | C18: ='Financial Inputs'!$D$21 -> 41465.76 | D18: ='Financial Inputs'!$E$21 -> 56144.57 | E18: =INDEX(B18:D18,MATCH($B$9,$B$12:$D$12,0)) -> 56144.57 | F18: Lower | G18: =IF(AND(ISNUMBER(C18),ISNUMBER(D18)),IF(D18=C18,"No change",IF((D18>C18)=(F18="Higher"),"Favourable","Watch")),"n/a") -> Watch
A19: Borrowings / total assets | B19: ='Financial Ratios'!C14 -> 0.43674529 | C19: ='Financial Ratios'!D14 -> 0.43652357 | D19: ='Financial Ratios'!E14 -> 0.4080616 | E19: =INDEX(B19:D19,MATCH($B$9,$B$12:$D$12,0)) -> 0.4080616 | F19: Lower | G19: =IF(AND(ISNUMBER(C19),ISNUMBER(D19)),IF(D19=C19,"No change",IF((D19>C19)=(F19="Higher"),"Favourable","Watch")),"n/a") -> Favourable
A20: Borrowings growth (YoY) | B20: ='Financial Ratios'!C11 -> n/a | C20: ='Financial Ratios'!D11 -> 0.17411974 | D20: ='Financial Ratios'!E11 -> 0.069665301 | E20: =INDEX(B20:D20,MATCH($B$9,$B$12:$D$12,0)) -> 0.069665301 | F20: Lower | G20: =IF(AND(ISNUMBER(C20),ISNUMBER(D20)),IF(D20=C20,"No change",IF((D20>C20)=(F20="Higher"),"Favourable","Watch")),"n/a") -> Favourable
A21: (Cash + other bank balances) / borrowings – gross | B21: ='Financial Ratios'!C17 -> 0.2881309 | C21: ='Financial Ratios'!D17 -> 0.17012741 | D21: ='Financial Ratios'!E17 -> 0.2467207 | E21: =INDEX(B21:D21,MATCH($B$9,$B$12:$D$12,0)) -> 0.2467207 | F21: Higher | G21: =IF(AND(ISNUMBER(C21),ISNUMBER(D21)),IF(D21=C21,"No change",IF((D21>C21)=(F21="Higher"),"Favourable","Watch")),"n/a") -> Favourable
A22: Operating cash flow (₹ crore) | B22: ='Financial Inputs'!$C$29 -> -5629.95 | C22: ='Financial Inputs'!$D$29 -> -290.8 | D22: ='Financial Inputs'!$E$29 -> 11657.36 | E22: =INDEX(B22:D22,MATCH($B$9,$B$12:$D$12,0)) -> 11657.36 | F22: Higher | G22: =IF(AND(ISNUMBER(C22),ISNUMBER(D22)),IF(D22=C22,"No change",IF((D22>C22)=(F22="Higher"),"Favourable","Watch")),"n/a") -> Favourable
A23: CFO / borrowings | B23: ='Financial Ratios'!C19 -> -0.054552072 | C23: ='Financial Ratios'!D19 -> -0.0023998755 | D23: ='Financial Ratios'!E19 -> 0.089938703 | E23: =INDEX(B23:D23,MATCH($B$9,$B$12:$D$12,0)) -> 0.089938703 | F23: Higher | G23: =IF(AND(ISNUMBER(C23),ISNUMBER(D23)),IF(D23=C23,"No change",IF((D23>C23)=(F23="Higher"),"Favourable","Watch")),"n/a") -> Favourable
A24: Finance costs / revenue | B24: ='Financial Ratios'!C9 -> 0.053841696 | C24: ='Financial Ratios'!D9 -> 0.057052592 | D24: ='Financial Ratios'!E9 -> 0.048489384 | E24: =INDEX(B24:D24,MATCH($B$9,$B$12:$D$12,0)) -> 0.048489384 | F24: Lower | G24: =IF(AND(ISNUMBER(C24),ISNUMBER(D24)),IF(D24=C24,"No change",IF((D24>C24)=(F24="Higher"),"Favourable","Watch")),"n/a") -> Favourable
A25: FS gross Stage 3 / gross loans | B25: ='Fin Services Asset Quality'!B19 -> 0.038702208 | C25: ='Fin Services Asset Quality'!C19 -> 0.040673705 | D25: ='Fin Services Asset Quality'!D19 -> 0.034154674 | E25: =INDEX(B25:D25,MATCH($B$9,$B$12:$D$12,0)) -> 0.034154674 | F25: Lower | G25: =IF(AND(ISNUMBER(C25),ISNUMBER(D25)),IF(D25=C25,"No change",IF((D25>C25)=(F25="Higher"),"Favourable","Watch")),"n/a") -> Favourable
A26: FS net Stage 3 / net carrying amount | B26: ='Fin Services Asset Quality'!B20 -> 0.016803746 | C26: ='Fin Services Asset Quality'!C20 -> 0.018695138 | D26: ='Fin Services Asset Quality'!D20 -> 0.014437396 | E26: =INDEX(B26:D26,MATCH($B$9,$B$12:$D$12,0)) -> 0.014437396 | F26: Lower | G26: =IF(AND(ISNUMBER(C26),ISNUMBER(D26)),IF(D26=C26,"No change",IF((D26>C26)=(F26="Higher"),"Favourable","Watch")),"n/a") -> Favourable
A27: Signals are mechanical (direction vs prior year) and do not by themselves measure credit quality – e.g. rising borrowings can accompany a growing, asset-backed finance book. 'Gross' liquidity ratio does not adjust for restricted balances.
A29: 2. Positive credit indicators (formula-driven text)
A30: ="Revenue from operations rose from ₹"&TEXT('Financial Inputs'!$C$6,"#,##0.00")&" crore (FY2024) to ₹"&TEXT('Financial Inputs'!$E$6,"#,##0.00")&" crore (FY2026), +"&TEXT('Financial Inputs'!$E$6/'Financial Inputs'!$C$6-1,"0.0%")&" cumulatively." -> Revenue from operations rose from ₹1,39,078.27 crore (FY2024) to ₹1,97,792.78 crore (FY2026), +42.2% cumulatively.
A31: ="PBT margin improved from "&TEXT('Financial Ratios'!C7,"0.00%")&" (FY2024) to "&TEXT('Financial Ratios'!E7,"0.00%")&" (FY2026); consolidated profit margin from "&TEXT('Financial Ratios'!C8,"0.00%")&" to "&TEXT('Financial Ratios'!E8,"0.00%")&"." -> PBT margin improved from 11.49% (FY2024) to 12.73% (FY2026); consolidated profit margin from 8.82% to 9.41%.
A32: ="Borrowings grew more slowly in FY2026 ("&TEXT('Financial Ratios'!E11,"0.0%")&") than in FY2025 ("&TEXT('Financial Ratios'!D11,"0.0%")&"); finance costs / revenue eased to "&TEXT('Financial Ratios'!E9,"0.00%")&"." -> Borrowings grew more slowly in FY2026 (7.0%) than in FY2025 (17.4%); finance costs / revenue eased to 4.85%.
A33: ="Operating cash flow improved to "&IF('Financial Inputs'!$E$29<0,"-","")&"₹"&TEXT(ABS('Financial Inputs'!$E$29),"#,##0.00")&" crore in FY2026 from "&IF('Financial Inputs'!$D$29<0,"-","")&"₹"&TEXT(ABS('Financial Inputs'!$D$29),"#,##0.00")&" crore in FY2025 and "&IF('Financial Inputs'!$C$29<0,"-","")&"₹"&TEXT(ABS('Financial Inputs'!$C$29),"#,##0.00")&" crore in FY2024." -> Operating cash flow improved to ₹11,657.36 crore in FY2026 from -₹290.80 crore in FY2025 and -₹5,629.95 crore in FY2024.
A34: ="Financial Services Stage 3 ratios improved in FY2026: gross "&TEXT('Fin Services Asset Quality'!D19,"0.00%")&" (FY2025 "&TEXT('Fin Services Asset Quality'!C19,"0.00%")&"); net "&TEXT('Fin Services Asset Quality'!D20,"0.00%")&" (FY2025 "&TEXT('Fin Services Asset Quality'!C20,"0.00%")&"); Stage 3 coverage "&TEXT('Fin Services Asset Quality'!D31,"0.0%")&"." -> Financial Services Stage 3 ratios improved in FY2026: gross 3.42% (FY2025 4.07%); net 1.44% (FY2025 1.87%); Stage 3 coverage 59.0%.
A35: CRISIL (18 Sep 2026) reaffirmed its high ratings – NCDs CRISIL AAA/Stable; short-term bank facilities and commercial paper CRISIL A1+. External agency opinion – not a zero-risk statement.
A36: ="All four segments reported higher segment results in FY2026 (total ₹"&TEXT('Segment Analysis'!D21,"#,##0.00")&" crore vs ₹"&TEXT('Segment Analysis'!C21,"#,##0.00")&" crore), giving diversified earnings." -> All four segments reported higher segment results in FY2026 (total ₹23,383.54 crore vs ₹18,463.59 crore), giving diversified earnings.
A38: 3. Key risks and watch-points (formula-driven text)
A39: ="Borrowings excluding leases reached ₹"&TEXT('Financial Inputs'!$E$22,"#,##0.00")&" crore ("&TEXT('Financial Ratios'!E14,"0.0%")&" of total assets). Read with the captive Financial Services book – Financial Services is "&TEXT('Segment Analysis'!D109,"0.0%")&" of FY2026 segment assets." -> Borrowings excluding leases reached ₹1,29,614.50 crore (40.8% of total assets). Read with the captive Financial Services book – Financial Services is 57.5% of FY2026 segment assets.
A40: ="Current borrowings reached ₹"&TEXT('Financial Inputs'!$E$21,"#,##0.00")&" crore ("&TEXT('Financial Ratios'!E15,"0.0%")&" of borrowings; short-term ₹"&TEXT('Financial Inputs'!$E$27,"#,##0.00")&" crore plus current maturities ₹"&TEXT('Financial Inputs'!$E$28,"#,##0.00")&" crore). Gross cash + bank balances cover "&TEXT('Debt Maturity & Liquidity'!D66,"0.00")&"x of borrowings principal due within 1 year." -> Current borrowings reached ₹56,144.57 crore (43.3% of borrowings; short-term ₹18,949.89 crore plus current maturities ₹37,194.68 crore). Gross cash + bank balances cover 0.57x of borrowings principal due within 1 year.
A41: ="Investing cash outflows remained substantial (₹"&TEXT(-'Financial Inputs'!$E$30,"#,##0.00")&" crore in FY2026). CFO + investing (simplified proxy, NOT free cash flow) was "&IF('Financial Ratios'!E21<0,"-","")&"₹"&TEXT(ABS('Financial Ratios'!E21),"#,##0.00")&" crore." -> Investing cash outflows remained substantial (₹17,707.39 crore in FY2026). CFO + investing (simplified proxy, NOT free cash flow) was -₹6,050.03 crore.
A42: The FY2026 operating-cash-flow rebound needs a sustainability assessment: CFO was negative in FY2024–FY2025, and consolidated CFO may be affected by Financial Services loan flows and working-capital timing (verify in the cash-flow statement).
A43: ="Other bank balances (₹"&TEXT('Financial Inputs'!$E$24,"#,##0.00")&" crore) may not all be freely available; the cash + bank ratio ("&TEXT('Financial Ratios'!E17,"0.0%")&") is a gross indicator." -> Other bank balances (₹27,686.34 crore) may not all be freely available; the cash + bank ratio (24.7%) is a gross indicator.
A44: ="Financial Services loan growth ("&TEXT('Fin Services Asset Quality'!D24,"0.0%")&" gross in FY2026) and ECL coverage require monitoring; Stage 2 + Stage 3 share is "&TEXT('Fin Services Asset Quality'!D23,"0.0%")&"; Stage 2 ECL rate "&TEXT('Fin Services Asset Quality'!D16,"0.0%")&"." -> Financial Services loan growth (12.7% gross in FY2026) and ECL coverage require monitoring; Stage 2 + Stage 3 share is 8.2%; Stage 2 ECL rate 8.0%.
...

Sheet Financial Inputs
A1: Financial Inputs – Mahindra & Mahindra Limited (Consolidated)
A2: ₹ crore unless stated. Fiscal years end 31 March. Source: figures supplied for this project from the annual reports (see Source Register). Independent educational project – not an official Wells Fargo assessment or lending decision.
A3: Colour key: Blue = hard-coded input (as supplied) | Black = formula | Green = link to another sheet | Grey italic = not supplied / not applicable (never estimated)
A5: Section | B5: Metric | C5: FY2024 | D5: FY2025 | E5: FY2026 | F5: Unit | G5: Source / note
A6: Income statement | B6: Revenue from operations | C6: 139078.27 | D6: 159210.82 | E6: 197792.78 | F6: ₹ crore | G6: Basis for ALL revenue growth and margin ratios. Not mixed with total income.
A7: Income statement | B7: Other income | C7: 2176.42 | D7: 2181.05 | E7: 3445.79 | F7: ₹ crore | G7: Consolidated; as supplied.
A8: Income statement | B8: Total income (as reported) | C8: 141254.69 | D8: 161391.87 | E8: 202084.34 | F8: ₹ crore | G8: FLAG: FY2026 reported total income exceeds revenue from operations + other income by ₹845.77 crore (equal to the segment-revenue difference). Retained as reported – see Verification Log.
A9: Income statement | B9: Finance costs | C9: 7488.21 | D9: 9083.39 | E9: 9590.85 | F9: ₹ crore | G9: Consolidated; as supplied.
A10: Income statement | B10: Total expenses | C10: 126398.33 | D10: 143849.67 | E10: 178571.55 | F10: ₹ crore | G10: Consolidated; as supplied.
A11: Income statement | B11: Exceptional items | C11: Not supplied | D11: 0 | E11: -292.94 | F11: ₹ crore | G11: FY2026 negative ₹292.94 crore; FY2025 nil; FY2024 not supplied.
A12: Income statement | B12: PBT before share of associates/JVs and tax | C12: 14856.36 | D12: 17542.2 | E12: 23219.85 | F12: ₹ crore | G12: Consolidated; as supplied.
A13: Income statement | B13: PBT before exceptional items, share of associates/JVs and tax | C13: Not supplied | D13: =D12 -> 17542.2 | E13: 23512.79 | F13: ₹ crore | G13: FY2025 derived (formula): exceptional items were nil, so equals PBT before associates/JVs. FY2024 not supplied.
A14: Income statement | B14: Share of profit of associates/JVs | C14: 1121.43 | D14: 1537.42 | E14: 1964.91 | F14: ₹ crore | G14: Consolidated; as supplied.
A15: Income statement | B15: Profit before tax | C15: 15977.79 | D15: 19079.62 | E15: 25184.76 | F15: ₹ crore | G15: Consolidated; as supplied.
A16: Income statement | B16: Total consolidated profit | C16: 12269.82 | D16: 14073.17 | E16: 18621.71 | F16: ₹ crore | G16: Consolidated; as supplied.
A17: Income statement | B17: Profit attributable to owners | C17: 11268.64 | D17: 12929.1 | E17: 17098.85 | F17: ₹ crore | G17: Consolidated; as supplied.
A18: Income statement | B18: Basic EPS | C18: 101.14 | D18: 115.91 | E18: 153.1 | F18: ₹ | G18: Consolidated; as supplied.
A19: Balance sheet | B19: Total assets | C19: 236300.73 | D19: 277586.27 | E19: 317634.64 | F19: ₹ crore | G19: Consolidated; as supplied.
A20: Balance sheet | B20: Non-current borrowings | C20: 67719.69 | D20: 79707.19 | E20: 73469.93 | F20: ₹ crore | G20: Consolidated; as supplied.
A21: Balance sheet | B21: Current borrowings | C21: 35483.54 | D21: 41465.76 | E21: 56144.57 | F21: ₹ crore | G21: Includes current maturities of long-term borrowings.
A22: Balance sheet | B22: Total borrowings excluding leases | C22: 103203.23 | D22: 121172.95 | E22: 129614.5 | F22: ₹ crore | G22: Excludes lease liabilities. Not the same as total contractual financial liabilities.
A23: Balance sheet | B23: Cash and cash equivalents | C23: 4530.1 | D23: 4923.89 | E23: 4292.24 | F23: ₹ crore | G23: Consolidated; as supplied.
A24: Balance sheet | B24: Other bank balances | C24: 25205.94 | D24: 15690.95 | E24: 27686.34 | F24: ₹ crore | G24: May include restricted / earmarked balances – composition not supplied.
A25: Balance sheet | B25: Non-current lease liabilities | C25: Not supplied | D25: 3170.14 | E25: 3651.83 | F25: ₹ crore | G25: FY2024 not supplied.
A26: Balance sheet | B26: Current lease liabilities | C26: Not supplied | D26: 606.22 | E26: 696.82 | F26: ₹ crore | G26: FY2024 not supplied.
A27: Balance sheet | B27: of which: short-term borrowings (within current borrowings) | C27: Not supplied | D27: 8193.11 | E27: 18949.89 | F27: ₹ crore | G27: FY2024 split not supplied.
A28: Balance sheet | B28: of which: current maturities of long-term borrowings | C28: Not supplied | D28: 33272.65 | E28: 37194.68 | F28: ₹ crore | G28: FY2024 split not supplied.
A29: Cash flow | B29: Operating cash flow | C29: -5629.95 | D29: -290.8 | E29: 11657.36 | F29: ₹ crore | G29: Negative in FY2024–FY2025. Consolidated CFO may include Financial Services loan flows – verify in cash-flow statement.
A30: Cash flow | B30: Investing cash flow | C30: -5597.77 | D30: -15159.5 | E30: -17707.39 | F30: ₹ crore | G30: Consolidated; as supplied.
A31: Cash flow | B31: Financing cash flow | C31: 12281.41 | D31: 15834.11 | E31: 5391.04 | F31: ₹ crore | G31: Consolidated; as supplied.
A32: Cash flow | B32: Net change in cash equivalents (as reported) | C32: 3493.41 | D32: 383.81 | E32: -658.99 | F32: ₹ crore | G32: FLAG: FY2024 CFO + CFI + CFF = ₹1,053.69 crore, not ₹3,493.41 crore – see Verification Log.
A34: Data handling: figures are retained exactly as supplied. 'Not supplied' cells are never estimated or back-solved; any ratio needing them shows 'n/a'. Derivative-liabilities tables are excluded and are not combined with any borrowings or maturity figures.

Sheet Financial Ratios
A1: Financial Ratios – Consolidated
A2: All ratios are live formulas on 'Financial Inputs'. Revenue = revenue from operations throughout (never total income). FY2024 growth rates are n/a because FY2023 was not supplied.
A3: Colour key: Blue = hard-coded input (as supplied) | Black = formula | Green = link to another sheet | Grey italic = not supplied / not applicable (never estimated)
A5: Category | B5: Ratio | C5: FY2024 | D5: FY2025 | E5: FY2026 | F5: Definition (formula basis) | G5: Analyst comment
A6: Growth | B6: Revenue growth (YoY) | C6: n/a | D6: ='Financial Inputs'!$D$6/'Financial Inputs'!$C$6-1 -> 0.14475698 | E6: ='Financial Inputs'!$E$6/'Financial Inputs'!$D$6-1 -> 0.24233252 | F6: Revenue from operations(t) / Revenue from operations(t-1) − 1 | G6: Strong growth; FY2026 +24.2%.
A7: Profitability | B7: PBT margin | C7: ='Financial Inputs'!$C$15/'Financial Inputs'!$C$6 -> 0.11488344 | D7: ='Financial Inputs'!$D$15/'Financial Inputs'!$D$6 -> 0.11983871 | E7: ='Financial Inputs'!$E$15/'Financial Inputs'!$E$6 -> 0.12732902 | F7: Profit before tax / Revenue from operations | G7: Improved from c.11.49% to c.12.73%. PBT includes share of associates/JVs.
A8: Profitability | B8: Consolidated profit margin | C8: ='Financial Inputs'!$C$16/'Financial Inputs'!$C$6 -> 0.088222409 | D8: ='Financial Inputs'!$D$16/'Financial Inputs'!$D$6 -> 0.088393301 | E8: ='Financial Inputs'!$E$16/'Financial Inputs'!$E$6 -> 0.094147572 | F8: Total consolidated profit / Revenue from operations | G8: Improved from c.8.82% to c.9.41%.
A9: Profitability | B9: Finance costs / revenue | C9: ='Financial Inputs'!$C$9/'Financial Inputs'!$C$6 -> 0.053841696 | D9: ='Financial Inputs'!$D$9/'Financial Inputs'!$D$6 -> 0.057052592 | E9: ='Financial Inputs'!$E$9/'Financial Inputs'!$E$6 -> 0.048489384 | F9: Finance costs / Revenue from operations | G9: Rose in FY2025, eased in FY2026. Finance costs include the captive Financial Services business, where interest is a cost of goods sold.
A10: Growth | B10: Total assets growth (YoY) | C10: n/a | D10: ='Financial Inputs'!$D$19/'Financial Inputs'!$C$19-1 -> 0.17471609 | E10: ='Financial Inputs'!$E$19/'Financial Inputs'!$D$19-1 -> 0.1442736 | F10: Total assets(t) / Total assets(t-1) − 1 | G10: Asset growth largely tracks business expansion incl. Financial Services loan book.
A11: Growth | B11: Borrowings growth (total excl. leases, YoY) | C11: n/a | D11: ='Financial Inputs'!$D$22/'Financial Inputs'!$C$22-1 -> 0.17411974 | E11: ='Financial Inputs'!$E$22/'Financial Inputs'!$D$22-1 -> 0.069665301 | F11: Total borrowings excl. leases(t) / (t-1) − 1 | G11: FY2026 growth slower than FY2025.
A12: Growth | B12: Current borrowings growth (YoY) | C12: n/a | D12: ='Financial Inputs'!$D$21/'Financial Inputs'!$C$21-1 -> 0.16859141 | E12: ='Financial Inputs'!$E$21/'Financial Inputs'!$D$21-1 -> 0.35399834 | F12: Current borrowings(t) / (t-1) − 1 | G12: Current borrowings rose sharply in FY2026 – refinancing/rollover profile to monitor.
A13: Growth | B13: Non-current borrowings growth (YoY) | C13: n/a | D13: ='Financial Inputs'!$D$20/'Financial Inputs'!$C$20-1 -> 0.17701646 | E13: ='Financial Inputs'!$E$20/'Financial Inputs'!$D$20-1 -> -0.078252163 | F13: Non-current borrowings(t) / (t-1) − 1 | G13: Non-current borrowings fell in FY2026 as more debt moved into current maturities.
A14: Leverage | B14: Borrowings (excl. leases) / total assets | C14: ='Financial Inputs'!$C$22/'Financial Inputs'!$C$19 -> 0.43674529 | D14: ='Financial Inputs'!$D$22/'Financial Inputs'!$D$19 -> 0.43652357 | E14: ='Financial Inputs'!$E$22/'Financial Inputs'!$E$19 -> 0.4080616 | F14: Total borrowings excl. leases / Total assets | G14: Roughly stable c.41–44%. Read with the captive Financial Services loan book (see Segment Analysis).
A15: Leverage | B15: Current borrowings / total borrowings (excl. leases) | C15: ='Financial Inputs'!$C$21/'Financial Inputs'!$C$22 -> 0.34382199 | D15: ='Financial Inputs'!$D$21/'Financial Inputs'!$D$22 -> 0.34220311 | E15: ='Financial Inputs'!$E$21/'Financial Inputs'!$E$22 -> 0.43316581 | F15: Current borrowings / Total borrowings excl. leases | G15: Supplementary. Share of debt due within 12 months rose in FY2026.
A16: Liquidity | B16: Cash and cash equivalents / borrowings | C16: ='Financial Inputs'!$C$23/'Financial Inputs'!$C$22 -> 0.043894944 | D16: ='Financial Inputs'!$D$23/'Financial Inputs'!$D$22 -> 0.040635224 | E16: ='Financial Inputs'!$E$23/'Financial Inputs'!$E$22 -> 0.033115431 | F16: Cash and cash equivalents / Total borrowings excl. leases | G16: Low on a cash-only basis; the group also holds other bank balances (next row).
A17: Liquidity | B17: (Cash + other bank balances) / borrowings – GROSS INDICATOR | C17: =('Financial Inputs'!$C$23+'Financial Inputs'!$C$24)/'Financial Inputs'!$C$22 -> 0.2881309 | D17: =('Financial Inputs'!$D$23+'Financial Inputs'!$D$24)/'Financial Inputs'!$D$22 -> 0.17012741 | E17: =('Financial Inputs'!$E$23+'Financial Inputs'!$E$24)/'Financial Inputs'!$E$22 -> 0.2467207 | F17: (Cash and cash equivalents + Other bank balances) / Total borrowings excl. leases | G17: GROSS indicator: does NOT adjust for restricted, earmarked or encumbered bank balances. Treat as an upper bound of freely available liquidity.
A18: Cash flow | B18: CFO / revenue | C18: ='Financial Inputs'!$C$29/'Financial Inputs'!$C$6 -> -0.040480443 | D18: ='Financial Inputs'!$D$29/'Financial Inputs'!$D$6 -> -0.001826509 | E18: ='Financial Inputs'!$E$29/'Financial Inputs'!$E$6 -> 0.058937237 | F18: Operating cash flow / Revenue from operations | G18: Turned positive in FY2026; sustainability needs assessment.
A19: Cash flow | B19: CFO / borrowings | C19: ='Financial Inputs'!$C$29/'Financial Inputs'!$C$22 -> -0.054552072 | D19: ='Financial Inputs'!$D$29/'Financial Inputs'!$D$22 -> -0.0023998755 | E19: ='Financial Inputs'!$E$29/'Financial Inputs'!$E$22 -> 0.089938703 | F19: Operating cash flow / Total borrowings excl. leases | G19: Negative in FY2024–FY2025, c.9.0% in FY2026.
A20: Supplementary | B20: Indicative interest cover (x) | C20: =('Financial Inputs'!$C$12+'Financial Inputs'!$C$9)/'Financial Inputs'!$C$9 -> 2.9839668 | D20: =('Financial Inputs'!$D$12+'Financial Inputs'!$D$9)/'Financial Inputs'!$D$9 -> 2.9312393 | E20: =('Financial Inputs'!$E$12+'Financial Inputs'!$E$9)/'Financial Inputs'!$E$9 -> 3.4210419 | F20: (PBT before associates/JVs + Finance costs) / Finance costs | G20: Indicative only. Finance costs include the Financial Services lending business, so consolidated cover is not comparable with industrial-company cover.
A21: Cash-flow proxy | B21: CFO + investing cash flow (₹ crore) – SIMPLIFIED PROXY, NOT FREE CASH FLOW | C21: ='Financial Inputs'!$C$29+'Financial Inputs'!$C$30 -> -11227.72 | D21: ='Financial Inputs'!$D$29+'Financial Inputs'!$D$30 -> -15450.3 | E21: ='Financial Inputs'!$E$29+'Financial Inputs'!$E$30 -> -6050.03 | F21: Operating cash flow + Investing cash flow (investing is negative = outflow) | G21: Simplified proxy only. Investing flows include purchases of investments/bank deposits and capex; this is NOT a definition of free cash flow (which would use capex only).
B23: Formula-error check – count of error cells in ratio table | C23: =SUMPRODUCT(--ISERROR(C6:E21)) -> 0 | D23: =IF(C23=0,"OK","FLAG") -> OK
A25: Reading the ratios: a high headline borrowings figure does not by itself indicate distress. Consolidated debt includes the borrowings that fund the captive Financial Services loan book, which is matched by loan assets; judge leverage alongside asset quality, liquidity and cash flow (see Executive Dashboard).

Sheet Segment Analysis
A1: Segment Analysis – Consolidated segment disclosures
A2: ₹ crore. Segment result is after share of associates/JVs. Segment figures are NOT reconciled to consolidated totals (definitions differ) – differences are shown, not forced.
A3: Colour key: Blue = hard-coded input (as supplied) | Black = formula | Green = link to another sheet | Grey italic = not supplied / not applicable (never estimated)
A5: A. External revenue (input)
A6: Segment | B6: FY2024 | C6: FY2025 | D6: FY2026 | E6: Unit | F6: Note
A7: Automotive | B7: 75488.31 | C7: 90424.08 | D7: 117363.87 | E7: ₹ crore
A8: Farm Equipment | B8: 33398.87 | C8: 35315.81 | D8: 42397.44 | E8: ₹ crore
A9: Financial Services | B9: 15652.02 | C9: 18295.83 | D9: 20817.69 | E9: ₹ crore
A10: Industrial Businesses & Consumer Services | B10: 14539.07 | C10: 15175.1 | D10: 18059.55 | E10: ₹ crore
A11: Total (as reported) | B11: 139078.27 | C11: 159210.82 | D11: 198638.55 | E11: ₹ crore | F11: As supplied. FY2026 total differs in definition from consolidated revenue from operations – see reconciliation panel.
A12: Check: sum of segments (formula) | B12: =SUM(B7:B10) -> 139078.27 | C12: =SUM(C7:C10) -> 159210.82 | D12: =SUM(D7:D10) -> 198638.55 | E12: ₹ crore
A13: Check: sum of segments − reported total | B13: =B12-B11 -> 0 | C13: =C12-C11 -> 0 | D13: =D12-D11 -> 0 | E13: ₹ crore | F13: Should be nil (rounding tolerance ₹0.02 crore).
A15: B. Segment result after share of associates/JVs (input)
A16: Segment | B16: FY2024 | C16: FY2025 | D16: FY2026 | E16: Unit | F16: Note
A17: Automotive | B17: 6057.12 | C17: 7797.4 | D17: 10383.47 | E17: ₹ crore
A18: Farm Equipment | B18: 4326.62 | C18: 4946.65 | D18: 5516.9 | E18: ₹ crore
A19: Financial Services | B19: 2557.22 | C19: 3002.02 | D19: 3778.53 | E19: ₹ crore
A20: Industrial Businesses & Consumer Services | B20: 2259.12 | C20: 2717.52 | D20: 3704.64 | E20: ₹ crore
A21: Total (as reported) | B21: 15200.08 | C21: 18463.59 | D21: 23383.54 | E21: ₹ crore | F21: As supplied.
A22: Check: sum of segments (formula) | B22: =SUM(B17:B20) -> 15200.08 | C22: =SUM(C17:C20) -> 18463.59 | D22: =SUM(D17:D20) -> 23383.54 | E22: ₹ crore
A23: Check: sum of segments − reported total | B23: =B22-B21 -> 0 | C23: =C22-C21 -> 0 | D23: =D22-D21 -> 0 | E23: ₹ crore | F23: Should be nil (rounding tolerance ₹0.02 crore).
A25: C. Segment assets (input)
A26: Segment | B26: FY2024 | C26: FY2025 | D26: FY2026 | E26: Unit | F26: Note
A27: Automotive | B27: 39487.01 | C27: 47136.13 | D27: 54612.25 | E27: ₹ crore
A28: Farm Equipment | B28: 18078.13 | C28: 18309.67 | D28: 18755.5 | E28: ₹ crore
A29: Financial Services | B29: 120162.81 | C29: 139101.47 | D29: 155756.75 | E29: ₹ crore
A30: Industrial Businesses & Consumer Services | B30: 33910.13 | C30: 37376.19 | D30: 41763.13 | E30: ₹ crore
A31: Total (as reported) | B31: 211638.08 | C31: 241923.46 | D31: 270887.63 | E31: ₹ crore | F31: As supplied.
A32: Check: sum of segments (formula) | B32: =SUM(B27:B30) -> 211638.08 | C32: =SUM(C27:C30) -> 241923.46 | D32: =SUM(D27:D30) -> 270887.63 | E32: ₹ crore
A33: Check: sum of segments − reported total | B33: =B32-B31 -> 0 | C33: =C32-C31 -> 0 | D33: =D32-D31 -> 0 | E33: ₹ crore | F33: Should be nil (rounding tolerance ₹0.02 crore).
A35: D. Segment liabilities (input)
A36: Segment | B36: FY2024 | C36: FY2025 | D36: FY2026 | E36: Unit | F36: Note
A37: Automotive | B37: 22886.46 | C37: 29223.19 | D37: 37270.73 | E37: ₹ crore
A38: Farm Equipment | B38: 8642.38 | C38: 9308.13 | D38: 11057.77 | E38: ₹ crore
A39: Financial Services | B39: 103345.96 | C39: 122259.51 | D39: 131591.34 | E39: ₹ crore
A40: Industrial Businesses & Consumer Services | B40: 14074.04 | C40: 15976.86 | D40: 17931.66 | E40: ₹ crore
A41: Total (as reported) | B41: 148948.84 | C41: 176767.69 | D41: 197851.5 | E41: ₹ crore | F41: As supplied.
A42: Check: sum of segments (formula) | B42: =SUM(B37:B40) -> 148948.84 | C42: =SUM(C37:C40) -> 176767.69 | D42: =SUM(D37:D40) -> 197851.5 | E42: ₹ crore
A43: Check: sum of segments − reported total | B43: =B42-B41 -> 0 | C43: =C42-C41 -> 0 | D43: =D42-D41 -> 0 | E43: ₹ crore | F43: Should be nil (rounding tolerance ₹0.02 crore).
A45: E. External revenue growth (YoY) and 2-year CAGR
...

Sheet Fin Services Asset Quality
A1: Financial Services Asset Quality – Mahindra Finance segment loan book
A2: ₹ crore. Stage 3 = credit-impaired exposures; the supplied Financial Services definition includes borrowers 90 days past due. Annual credit cost is NOT calculated (flow data not supplied).
A3: Colour key: Blue = hard-coded input (as supplied) | Black = formula | Green = link to another sheet | Grey italic = not supplied / not applicable (never estimated)
A5: Metric | B5: FY2024 | C5: FY2025 | D5: FY2026 | E5: Unit | F5: Note
A6: A. Gross loan balances (input)
A7: Stage 1 gross balance | B7: Not supplied | C7: 112346.83 | D7: 128694.12 | E7: ₹ crore | F7: FY2024 not supplied.
A8: Stage 2 gross balance | B8: Not supplied | C8: 6981.83 | D8: 6757.4 | E8: ₹ crore | F8: FY2024 not supplied.
A9: Stage 3 gross balance | B9: 4146.74 | C9: 5059.32 | D9: 4789.9 | E9: ₹ crore
A10: Total gross loan balance | B10: 107144.79 | C10: 124387.98 | D10: 140241.42 | E10: ₹ crore
A11: B. Net carrying amounts (input)
A12: Stage 3 net carrying amount | B12: 1738.89 | C12: 2249.74 | D12: 1965.13 | E12: ₹ crore
A13: Total net carrying amount | B13: 103482.28 | C13: 120338.24 | D13: 136113.88 | E13: ₹ crore
A14: C. Expected credit loss (ECL) rates (input)
A15: Stage 1 ECL rate | B15: Not supplied | C15: 0.0052 | D15: 0.0059 | E15: % | F15: FY2024 not supplied.
A16: Stage 2 ECL rate | B16: Not supplied | C16: 0.0932 | D16: 0.0803 | E16: % | F16: FY2024 not supplied.
A17: Stage 3 ECL rate | B17: 0.5807 | C17: 0.5553 | D17: 0.5897 | E17: %
A18: D. Asset-quality ratios (formulas)
A19: Gross Stage 3 / gross loans | B19: =B9/B10 -> 0.038702208 | C19: =C9/C10 -> 0.040673705 | D19: =D9/D10 -> 0.034154674 | E19: % | F19: Key headline NPA-type ratio. Improved in FY2026.
A20: Net Stage 3 / net carrying amount | B20: =B12/B13 -> 0.016803746 | C20: =C12/C13 -> 0.018695138 | D20: =D12/D13 -> 0.014437396 | E20: % | F20: Net of ECL allowance. Improved in FY2026.
A21: Stage 1 share of gross loans | B21: n/a | C21: =C7/C10 -> 0.90319684 | D21: =D7/D10 -> 0.91766127 | E21: % | F21: FY2024 not computable (Stage 1 not supplied).
A22: Stage 2 share of gross loans | B22: n/a | C22: =C8/C10 -> 0.056129459 | D22: =D8/D10 -> 0.048184053 | E22: % | F22: Stage 2 = significant increase in credit risk (watch-list).
A23: Stage 2 + Stage 3 share of gross loans | B23: n/a | C23: =(C8+C9)/C10 -> 0.096803164 | D23: =(D8+D9)/D10 -> 0.082338727 | E23: % | F23: Combined stressed-and-impaired share; FY2024 not computable.
A24: Gross loan growth (YoY) | B24: n/a | C24: =C10/B10-1 -> 0.16093354 | D24: =D10/C10-1 -> 0.12745154 | E24: % | F24: Loan growth needs monitoring against underwriting quality.
A25: Net carrying amount growth (YoY) | B25: n/a | C25: =C13/B13-1 -> 0.1628874 | D25: =D13/C13-1 -> 0.13109416 | E25: %
A26: Stage 3 gross balance growth (YoY) | B26: n/a | C26: =C9/B9-1 -> 0.22007167 | D26: =D9/C9-1 -> -0.053252216 | E26: % | F26: Absolute Stage 3 balance fell in FY2026 while the loan book grew.
A27: E. ECL allowance analysis (formulas; allowance = gross − net)
A28: Implied total ECL allowance (gross − net) | B28: =B10-B13 -> 3662.51 | C28: =C10-C13 -> 4049.74 | D28: =D10-D13 -> 4127.54 | E28: ₹ crore | F28: Derived from supplied balances.
A29: Implied total allowance / gross loans | B29: =B28/B10 -> 0.03418281 | C29: =C28/C10 -> 0.032557326 | D29: =D28/D10 -> 0.029431676 | E29: % | F29: Overall ECL coverage of the loan book.
A30: Implied Stage 3 allowance (gross − net) | B30: =B9-B12 -> 2407.85 | C30: =C9-C12 -> 2809.58 | D30: =D9-D12 -> 2824.77 | E30: ₹ crore
A31: Implied Stage 3 coverage (allowance / gross Stage 3) | B31: =B30/B9 -> 0.58066095 | C31: =C30/C9 -> 0.55532759 | D31: =D30/D9 -> 0.58973465 | E31: % | F31: Should agree with the supplied Stage 3 ECL rate.
A32: Difference vs supplied Stage 3 ECL rate (percentage points) | B32: =(B31-B17)*100 -> -0.0039047059 | C32: =(C31-C17)*100 -> 0.0027593432 | D32: =(D31-D17)*100 -> 0.0034649993 | E32: pp | F32: Consistency check; small differences reflect rounding of supplied rates.
A33: Implied Stage 1+2 allowance (total − Stage 3) | B33: =B28-B30 -> 1254.66 | C33: =C28-C30 -> 1240.16 | D33: =D28-D30 -> 1302.77 | E33: ₹ crore
A34: Calculated Stage 1+2 allowance (balance × ECL rate) | B34: n/a | C34: =C7*C15+C8*C16 -> 1234.9101 | D34: =D7*D15+D8*D16 -> 1301.9145 | E34: ₹ crore | F34: FY2024 not computable.
A35: Difference (implied − calculated) | B35: n/a | C35: =C33-C34 -> 5.249928 | D35: =D33-D34 -> 0.855472 | E35: ₹ crore | F35: Small residual expected because ECL rates are supplied to two decimals.
A36: Check: Stage 1+2+3 − total gross balance | B36: n/a | C36: =C7+C8+C9-C10 -> 0 | D36: =D7+D8+D9-D10 -> 0 | E36: ₹ crore | F36: Should be nil.
A37: F. Reference values quoted in the project brief (approximate, input) and agreement check
A38: Expected gross Stage 3 ratio (brief, approx.) | B38: 0.0387 | C38: 0.0407 | D38: 0.0342 | E38: % | F38: Rounded values from the brief.
A39: Expected net Stage 3 ratio (brief, approx.) | B39: 0.0168 | C39: 0.0187 | D39: 0.0144 | E39: % | F39: Rounded values from the brief.
A40: Gross: calculated − expected (pp) | B40: =(B19-B38)*100 -> 0.00022084788 | C40: =(C19-C38)*100 -> -0.0026295033 | D40: =(D19-D38)*100 -> -0.0045325867 | E40: pp | F40: Within rounding (< 0.02 pp).
A41: Net: calculated − expected (pp) | B41: =(B20-B39)*100 -> 0.00037464965 | C41: =(C20-C39)*100 -> -0.00048620289 | D41: =(D20-D39)*100 -> 0.0037396098 | E41: pp | F41: Within rounding (< 0.02 pp).
...

Sheet Debt Maturity & Liquidity
A1: Debt Maturity & Liquidity – Contractual cash-flow analysis
A2: ₹ crore. The maturity tables are UNDISCOUNTED contractual cash flows incl. principal, interest, trade payables and other financial liabilities – NOT equivalent to balance-sheet borrowings. Derivative liabilities are excluded.
A3: Colour key: Blue = hard-coded input (as supplied) | Black = formula | Green = link to another sheet | Grey italic = not supplied / not applicable (never estimated)
A5: A. Undiscounted contractual cash flows by maturity bucket (input)
A6: FY2026 – contractual maturity table
A7: Item (₹ crore, undiscounted) | B7: < 1 year | C7: 1–3 years | D7: 3–5 years | E7: > 5 years | F7: Total (all buckets) | G7: Note
A8: Borrowings principal | B8: 56144.57 | C8: 56005.88 | D8: 9455.84 | E8: 8093.25 | F8: =IF(COUNT(B8:E8)=0,"n/a",SUM(B8:E8)) -> 129699.54
A9: Borrowings interest | B9: 7314.51 | C9: 7034.3 | D9: 2082.91 | E9: 3108.6 | F9: =IF(COUNT(B9:E9)=0,"n/a",SUM(B9:E9)) -> 19540.32
A10: Trade payables | B10: 37888.67 | C10: 0 | D10: 0 | E10: 0 | F10: =IF(COUNT(B10:E10)=0,"n/a",SUM(B10:E10)) -> 37888.67
A11: Financial guarantees | B11: Not listed | C11: Not listed | D11: Not listed | E11: Not listed | F11: =IF(COUNT(B11:E11)=0,"n/a",SUM(B11:E11)) -> n/a | G11: Row not listed in the supplied FY2026 table; not assumed to be zero.
A12: Lease liabilities including interest | B12: 789.82 | C12: 1139.31 | D12: 1035.54 | E12: 2415.98 | F12: =IF(COUNT(B12:E12)=0,"n/a",SUM(B12:E12)) -> 5380.65
A13: Other financial liabilities | B13: 4168.64 | C13: 397.87 | D13: 10.79 | E13: 129.8 | F13: =IF(COUNT(B13:E13)=0,"n/a",SUM(B13:E13)) -> 4707.1
A14: Reported total contractual cash flows | B14: 106306.21 | C14: 64577.36 | D14: 12585.08 | E14: 13747.63 | F14: =SUM(B14:E14) -> 197216.28 | G14: As reported (input).
A15: Check: sum of listed items (formula) | B15: =SUM(B8:B13) -> 106306.21 | C15: =SUM(C8:C13) -> 64577.36 | D15: =SUM(D8:D13) -> 12585.08 | E15: =SUM(E8:E13) -> 13747.63 | F15: =SUM(B15:E15) -> 197216.28
A16: Check: sum of items − reported total | B16: =B15-B14 -> 0 | C16: =C15-C14 -> 0 | D16: =D15-D14 -> 0 | E16: =E15-E14 -> 0 | F16: =F15-F14 -> 0 | G16: Should be nil (tolerance ₹0.02 crore).
A18: FY2025 – contractual maturity table
A19: Item (₹ crore, undiscounted) | B19: < 1 year | C19: 1–3 years | D19: 3–5 years | E19: > 5 years | F19: Total (all buckets) | G19: Note
A20: Borrowings principal | B20: 41465.76 | C20: 56776.23 | D20: 15067.65 | E20: 8211.62 | F20: =IF(COUNT(B20:E20)=0,"n/a",SUM(B20:E20)) -> 121521.26
A21: Borrowings interest | B21: 7629.35 | C21: 8499.08 | D21: 2575.18 | E21: 3451.33 | F21: =IF(COUNT(B21:E21)=0,"n/a",SUM(B21:E21)) -> 22154.94
A22: Trade payables | B22: 30855.3 | C22: 0 | D22: 0 | E22: 0 | F22: =IF(COUNT(B22:E22)=0,"n/a",SUM(B22:E22)) -> 30855.3
A23: Financial guarantees | B23: 572.29 | C23: 0 | D23: 0 | E23: 0 | F23: =IF(COUNT(B23:E23)=0,"n/a",SUM(B23:E23)) -> 572.29
A24: Lease liabilities including interest | B24: 832.48 | C24: 1240.61 | D24: 969.66 | E24: 2017.74 | F24: =IF(COUNT(B24:E24)=0,"n/a",SUM(B24:E24)) -> 5060.49
A25: Other financial liabilities | B25: 3232.76 | C25: 480.94 | D25: 14.26 | E25: 110.37 | F25: =IF(COUNT(B25:E25)=0,"n/a",SUM(B25:E25)) -> 3838.33
A26: Reported total contractual cash flows | B26: 84587.94 | C26: 66996.86 | D26: 18626.75 | E26: 13791.06 | F26: =SUM(B26:E26) -> 184002.61 | G26: As reported (input).
A27: Check: sum of listed items (formula) | B27: =SUM(B20:B25) -> 84587.94 | C27: =SUM(C20:C25) -> 66996.86 | D27: =SUM(D20:D25) -> 18626.75 | E27: =SUM(E20:E25) -> 13791.06 | F27: =SUM(B27:E27) -> 184002.61
A28: Check: sum of items − reported total | B28: =B27-B26 -> 0 | C28: =C27-C26 -> 0 | D28: =D27-D26 -> 0 | E28: =E27-E26 -> 0 | F28: =F27-F26 -> 0 | G28: Should be nil (tolerance ₹0.02 crore).
A30: FY2024 – contractual maturity table
A31: Item (₹ crore, undiscounted) | B31: < 1 year | C31: 1–3 years | D31: 3–5 years | E31: > 5 years | F31: Total (all buckets) | G31: Note
A32: Borrowings principal | B32: 35483.54 | C32: 46077.06 | D32: 12469.49 | E32: 9274.33 | F32: =IF(COUNT(B32:E32)=0,"n/a",SUM(B32:E32)) -> 103304.42
A33: Borrowings interest | B33: 6804.92 | C33: 7879.33 | D33: 2504.01 | E33: 3860.15 | F33: =IF(COUNT(B33:E33)=0,"n/a",SUM(B33:E33)) -> 21048.41
A34: Trade payables | B34: 25665.64 | C34: 0 | D34: 0 | E34: 0 | F34: =IF(COUNT(B34:E34)=0,"n/a",SUM(B34:E34)) -> 25665.64
A35: Financial guarantees | B35: 557.34 | C35: 0 | D35: 0 | E35: 0 | F35: =IF(COUNT(B35:E35)=0,"n/a",SUM(B35:E35)) -> 557.34
A36: Lease liabilities including interest | B36: 756.13 | C36: 1018.88 | D36: 851.7 | E36: 1792.91 | F36: =IF(COUNT(B36:E36)=0,"n/a",SUM(B36:E36)) -> 4419.62
A37: Other financial liabilities | B37: 2763.81 | C37: 288.22 | D37: 177.57 | E37: 90.08 | F37: =IF(COUNT(B37:E37)=0,"n/a",SUM(B37:E37)) -> 3319.68
A38: Reported total contractual cash flows | B38: 72031.38 | C38: 55263.49 | D38: 16002.77 | E38: 15017.47 | F38: =SUM(B38:E38) -> 158315.11 | G38: As reported (input).
A39: Check: sum of listed items (formula) | B39: =SUM(B32:B37) -> 72031.38 | C39: =SUM(C32:C37) -> 55263.49 | D39: =SUM(D32:D37) -> 16002.77 | E39: =SUM(E32:E37) -> 15017.47 | F39: =SUM(B39:E39) -> 158315.11
A40: Check: sum of items − reported total | B40: =B39-B38 -> 0 | C40: =C39-C38 -> 0 | D40: =D39-D38 -> 0 | E40: =E39-E38 -> 0 | F40: =F39-F38 -> 0 | G40: Should be nil (tolerance ₹0.02 crore).
A42: B. Borrowings-principal reconciliation – maturity buckets vs balance-sheet borrowings (MANDATORY VERIFICATION FLAG)
A43: Item | B43: FY2024 | C43: FY2025 | D43: FY2026 | E43: Unit | G43: Note
A44: Sum of borrowings-principal maturity buckets | B44: =F32 -> 103304.42 | C44: =F20 -> 121521.26 | D44: =F8 -> 129699.54 | E44: ₹ crore | G44: From maturity tables above.
...

Sheet Source Register & Verif. Log
A1: Source Register & Verification Log
A2: Official sources used, arithmetic integrity checks across the supplied data, and data gaps. Checks compare supplied figures only – nothing has been adjusted.
A4: A. Source register
A5: ID | B5: Source name | C5: Reporting scope | D5: Date | E5: Publisher | F5: Page / note | G5: Source type | H5: Relevant figures used in this workbook | I5: Verification status | J5: Link
A6: S1 | B6: Mahindra & Mahindra – FY2026 Annual Report | C6: Consolidated (also standalone) | D6: Not supplied | E6: Mahindra & Mahindra Ltd | F6: Not recorded | G6: Company filing | H6: FY2026 (and comparative) consolidated income statement, balance sheet, cash flow; segment results/assets/liabilities; Financial Services staging, ECL and loan balances; contractual maturity table. | I6: Supplied by user – not independently re-checked against source | J6: https://www.mahindra.com/annual-report-FY2026/index.html
A7: S2 | B7: Mahindra & Mahindra – FY2025 Annual Report | C7: Consolidated (also standalone) | D7: Not supplied | E7: Mahindra & Mahindra Ltd | F7: Not recorded | G7: Company filing | H7: FY2025 and FY2024 comparative consolidated statements, segment data, Financial Services asset quality and maturity tables. | I7: Supplied by user – not independently re-checked against source | J7: https://www.mahindra.com/annual-report-FY2025/toc/
A8: S3 | B8: CRISIL rating rationale – Mahindra & Mahindra Limited | C8: Standalone indicators; instrument ratings | D8: 46283 | E8: CRISIL Ratings | F8: Not recorded | G8: Rating agency | H8: NCD AAA/Stable; short-term bank facilities and commercial paper A1+; rated amounts; standalone operating income, EBITDA, margins, interest coverage, accrual, Q1 FY2027. | I8: Supplied by user – not independently re-checked against source | J8: https://www.crisilratings.com/mnt/winshare/Ratings/RatingList/RatingDocs/MahindraandMahindraLimited_September%2018_%202026_RR_404981.html
A9: S4 | B9: Mahindra & Mahindra – Q4 and full-year FY26 standalone and consolidated results | C9: Standalone and consolidated | D9: Not supplied | E9: Mahindra & Mahindra Ltd | F9: Not recorded | G9: Press release | H9: Cross-reference for FY2026 headline revenue, profit and EPS. | I9: Supplied by user – not independently re-checked against source | J9: https://www.mahindra.com/news-room/press-release/en/financial-results-quarter-4-and-full-year-fy26-standalone-and-consolidated-results
A10: Source mapping above reflects the intended origin of the supplied figures; page/note references were not supplied and are not invented. Tracking parameters (utm_source) were removed from two of the supplied URLs. Update 'Verification status' and 'Page / note' as each figure is traced.
A12: B. Verification log – arithmetic and definition checks (live formulas)
A13: Tolerance | B13: Absolute tolerance (₹ crore, or percentage points for ratio checks): | C13: 0.02
A14: ID | B14: Check | C14: Scope | D14: Expected / reference | E14: Actual / compared | F14: Difference | G14: Auto status | H14: Treatment / analyst note | I14: Verification status | J14: Source ref
A15: V01 | B15: FY2024 borrowings-principal buckets vs balance-sheet borrowings | C15: Debt Maturity & Liquidity | D15: ='Financial Inputs'!$C$22 -> 103203.23 | E15: ='Debt Maturity & Liquidity'!F32 -> 103304.42 | F15: =E15-D15 -> 101.19 | G15: =IF(ABS(F15)<=$C$13,"OK","FLAG") -> FLAG | H15: Buckets exceed reported borrowings. Difference recorded; neither figure adjusted. Additional difference noticed in this check. | I15: Flagged – retained as supplied | J15: S1/S2
A16: V02 | B16: FY2025 borrowings-principal buckets vs balance-sheet borrowings | C16: Debt Maturity & Liquidity | D16: ='Financial Inputs'!$D$22 -> 121172.95 | E16: ='Debt Maturity & Liquidity'!F20 -> 121521.26 | F16: =E16-D16 -> 348.31 | G16: =IF(ABS(F16)<=$C$13,"OK","FLAG") -> FLAG | H16: Buckets exceed reported borrowings. Difference recorded; neither figure adjusted. Additional difference noticed in this check. | I16: Flagged – retained as supplied | J16: S1/S2
A17: V03 | B17: FY2026 borrowings-principal buckets vs balance-sheet borrowings (MANDATORY FLAG) | C17: Debt Maturity & Liquidity | D17: ='Financial Inputs'!$E$22 -> 129614.5 | E17: ='Debt Maturity & Liquidity'!F8 -> 129699.54 | F17: =E17-D17 -> 85.04 | G17: =IF(ABS(F17)<=$C$13,"OK","FLAG") -> FLAG | H17: Buckets exceed reported borrowings. Difference recorded; neither figure adjusted. FY2026: ₹85.04 crore. | I17: Flagged – retained as supplied | J17: S1/S2
A18: V04 | B18: FY2024 total income: reported vs revenue from operations + other income | C18: Financial Inputs | D18: ='Financial Inputs'!$C$8 -> 141254.69 | E18: ='Financial Inputs'!$C$6+'Financial Inputs'!$C$7 -> 141254.69 | F18: =E18-D18 -> 0 | G18: =IF(ABS(F18)<=$C$13,"OK","FLAG") -> OK | H18: Reconciles. | I18: Arithmetic check passed | J18: S1/S2
A19: V05 | B19: FY2025 total income: reported vs revenue from operations + other income | C19: Financial Inputs | D19: ='Financial Inputs'!$D$8 -> 161391.87 | E19: ='Financial Inputs'!$D$6+'Financial Inputs'!$D$7 -> 161391.87 | F19: =E19-D19 -> 0 | G19: =IF(ABS(F19)<=$C$13,"OK","FLAG") -> OK | H19: Reconciles. | I19: Arithmetic check passed | J19: S1/S2
A20: V06 | B20: FY2026 total income: reported vs revenue from operations + other income | C20: Financial Inputs | D20: ='Financial Inputs'!$E$8 -> 202084.34 | E20: ='Financial Inputs'!$E$6+'Financial Inputs'!$E$7 -> 201238.57 | F20: =E20-D20 -> -845.77 | G20: =IF(ABS(F20)<=$C$13,"OK","FLAG") -> FLAG | H20: FY2026 reported total income is ₹845.77 crore higher; same amount as the segment-revenue gap. Likely a definition difference – not confirmed. Retained as reported. | I20: Flagged – retained as supplied | J20: S1/S2
A21: V07 | B21: FY2024 revenue from operations vs segment external-revenue total | C21: Segment Analysis | D21: ='Financial Inputs'!$C$6 -> 139078.27 | E21: ='Segment Analysis'!B11 -> 139078.27 | F21: =E21-D21 -> 0 | G21: =IF(ABS(F21)<=$C$13,"OK","FLAG") -> OK | H21: Reconciles. | I21: Arithmetic check passed | J21: S1/S2
A22: V08 | B22: FY2025 revenue from operations vs segment external-revenue total | C22: Segment Analysis | D22: ='Financial Inputs'!$D$6 -> 159210.82 | E22: ='Segment Analysis'!C11 -> 159210.82 | F22: =E22-D22 -> 0 | G22: =IF(ABS(F22)<=$C$13,"OK","FLAG") -> OK | H22: Reconciles. | I22: Arithmetic check passed | J22: S1/S2
A23: V09 | B23: FY2026 revenue from operations vs segment external-revenue total | C23: Segment Analysis | D23: ='Financial Inputs'!$E$6 -> 197792.78 | E23: ='Segment Analysis'!D11 -> 198638.55 | F23: =E23-D23 -> 845.77 | G23: =IF(ABS(F23)<=$C$13,"OK","FLAG") -> FLAG | H23: Different source definitions; both preserved; no reconciliation forced. | I23: Flagged – retained as supplied | J23: S1/S2
A24: V10 | B24: FY2024 PBT before associates/JVs = total income − total expenses + exceptional items | C24: Financial Inputs | D24: ='Financial Inputs'!$C$12 -> 14856.36 | E24: ='Financial Inputs'!$C$8-'Financial Inputs'!$C$10+N('Financial Inputs'!$C$11) -> 14856.36 | F24: =E24-D24 -> 0 | G24: =IF(ABS(F24)<=$C$13,"OK","FLAG") -> OK | H24: FY2024 exceptional items not supplied (treated as nil only inside this check). | I24: Arithmetic check passed | J24: S1/S2
A25: V11 | B25: FY2025 PBT before associates/JVs = total income − total expenses + exceptional items | C25: Financial Inputs | D25: ='Financial Inputs'!$D$12 -> 17542.2 | E25: ='Financial Inputs'!$D$8-'Financial Inputs'!$D$10+N('Financial Inputs'!$D$11) -> 17542.2 | F25: =E25-D25 -> 0 | G25: =IF(ABS(F25)<=$C$13,"OK","FLAG") -> OK | H25: Reconciles. | I25: Arithmetic check passed | J25: S1/S2
A26: V12 | B26: FY2026 PBT before associates/JVs = total income − total expenses + exceptional items | C26: Financial Inputs | D26: ='Financial Inputs'!$E$12 -> 23219.85 | E26: ='Financial Inputs'!$E$8-'Financial Inputs'!$E$10+N('Financial Inputs'!$E$11) -> 23219.85 | F26: =E26-D26 -> 0 | G26: =IF(ABS(F26)<=$C$13,"OK","FLAG") -> OK | H26: Reconciles. | I26: Arithmetic check passed | J26: S1/S2
A27: V13 | B27: FY2024 PBT = PBT before associates/JVs + share of associates/JVs | C27: Financial Inputs | D27: ='Financial Inputs'!$C$15 -> 15977.79 | E27: ='Financial Inputs'!$C$12+'Financial Inputs'!$C$14 -> 15977.79 | F27: =E27-D27 -> 0 | G27: =IF(ABS(F27)<=$C$13,"OK","FLAG") -> OK | H27: Reconciles. | I27: Arithmetic check passed | J27: S1/S2
A28: V14 | B28: FY2025 PBT = PBT before associates/JVs + share of associates/JVs | C28: Financial Inputs | D28: ='Financial Inputs'!$D$15 -> 19079.62 | E28: ='Financial Inputs'!$D$12+'Financial Inputs'!$D$14 -> 19079.62 | F28: =E28-D28 -> 0 | G28: =IF(ABS(F28)<=$C$13,"OK","FLAG") -> OK | H28: Reconciles. | I28: Arithmetic check passed | J28: S1/S2
A29: V15 | B29: FY2026 PBT = PBT before associates/JVs + share of associates/JVs | C29: Financial Inputs | D29: ='Financial Inputs'!$E$15 -> 25184.76 | E29: ='Financial Inputs'!$E$12+'Financial Inputs'!$E$14 -> 25184.76 | F29: =E29-D29 -> 0 | G29: =IF(ABS(F29)<=$C$13,"OK","FLAG") -> OK | H29: Reconciles. | I29: Arithmetic check passed | J29: S1/S2
A30: V16 | B30: FY2024 borrowings: non-current + current = total (excl. leases) | C30: Financial Inputs | D30: ='Financial Inputs'!$C$22 -> 103203.23 | E30: ='Financial Inputs'!$C$20+'Financial Inputs'!$C$21 -> 103203.23 | F30: =E30-D30 -> 0 | G30: =IF(ABS(F30)<=$C$13,"OK","FLAG") -> OK | H30: Reconciles. | I30: Arithmetic check passed | J30: S1/S2
A31: V17 | B31: FY2025 borrowings: non-current + current = total (excl. leases) | C31: Financial Inputs | D31: ='Financial Inputs'!$D$22 -> 121172.95 | E31: ='Financial Inputs'!$D$20+'Financial Inputs'!$D$21 -> 121172.95 | F31: =E31-D31 -> 0 | G31: =IF(ABS(F31)<=$C$13,"OK","FLAG") -> OK | H31: Reconciles. | I31: Arithmetic check passed | J31: S1/S2
A32: V18 | B32: FY2026 borrowings: non-current + current = total (excl. leases) | C32: Financial Inputs | D32: ='Financial Inputs'!$E$22 -> 129614.5 | E32: ='Financial Inputs'!$E$20+'Financial Inputs'!$E$21 -> 129614.5 | F32: =E32-D32 -> 0 | G32: =IF(ABS(F32)<=$C$13,"OK","FLAG") -> OK | H32: Reconciles. | I32: Arithmetic check passed | J32: S1/S2
A33: V19 | B33: FY2025 current borrowings = short-term + current maturities of LT | C33: Financial Inputs | D33: ='Financial Inputs'!$D$21 -> 41465.76 | E33: ='Financial Inputs'!$D$27+'Financial Inputs'!$D$28 -> 41465.76 | F33: =E33-D33 -> 0 | G33: =IF(ABS(F33)<=$C$13,"OK","FLAG") -> OK | H33: Reconciles. | I33: Arithmetic check passed | J33: S1/S2
A34: V20 | B34: FY2026 current borrowings = short-term + current maturities of LT | C34: Financial Inputs | D34: ='Financial Inputs'!$E$21 -> 56144.57 | E34: ='Financial Inputs'!$E$27+'Financial Inputs'!$E$28 -> 56144.57 | F34: =E34-D34 -> 0 | G34: =IF(ABS(F34)<=$C$13,"OK","FLAG") -> OK | H34: Reconciles. | I34: Arithmetic check passed | J34: S1/S2
A35: V21 | B35: FY2024 CFO + investing + financing = net change in cash equivalents | C35: Financial Inputs | D35: ='Financial Inputs'!$C$32 -> 3493.41 | E35: ='Financial Inputs'!$C$29+'Financial Inputs'!$C$30+'Financial Inputs'!$C$31 -> 1053.69 | F35: =E35-D35 -> -2439.72 | G35: =IF(ABS(F35)<=$C$13,"OK","FLAG") -> FLAG | H35: FY2024 supplied components sum to ₹1,053.69 crore vs ₹3,493.41 crore reported (gap ₹2,439.72 crore). Possible transcription issue in the supplied FY2024 cash-flow inputs – verify against source. Retained as supplied; FY2024 cash-flow ratios carry this caveat. | I35: Flagged – retained as supplied | J35: S1/S2
A36: V22 | B36: FY2025 CFO + investing + financing = net change in cash equivalents | C36: Financial Inputs | D36: ='Financial Inputs'!$D$32 -> 383.81 | E36: ='Financial Inputs'!$D$29+'Financial Inputs'!$D$30+'Financial Inputs'!$D$31 -> 383.81 | F36: =E36-D36 -> 1.3073986e-12 | G36: =IF(ABS(F36)<=$C$13,"OK","FLAG") -> OK | H36: Reconciles. | I36: Arithmetic check passed | J36: S1/S2
A37: V23 | B37: FY2026 CFO + investing + financing = net change in cash equivalents | C37: Financial Inputs | D37: ='Financial Inputs'!$E$32 -> -658.99 | E37: ='Financial Inputs'!$E$29+'Financial Inputs'!$E$30+'Financial Inputs'!$E$31 -> -658.99 | F37: =E37-D37 -> 1.1368684e-12 | G37: =IF(ABS(F37)<=$C$13,"OK","FLAG") -> OK | H37: Reconciles. | I37: Arithmetic check passed | J37: S1/S2
A38: V24 | B38: FY2025 change in cash & cash equivalents (balance sheet) vs reported net change in cash | C38: Financial Inputs | D38: ='Financial Inputs'!$D$32 -> 383.81 | E38: ='Financial Inputs'!$D$23-'Financial Inputs'!$C$23 -> 393.79 | F38: =E38-D38 -> 9.98 | G38: =IF(ABS(F38)<=$C$13,"OK","INFO") -> INFO | H38: Informational: small differences can arise from items outside the cash-flow total (e.g., exchange effects, bank overdrafts). Not an error flag by itself. | I38: Informational | J38: S1/S2
A39: V25 | B39: FY2026 change in cash & cash equivalents (balance sheet) vs reported net change in cash | C39: Financial Inputs | D39: ='Financial Inputs'!$E$32 -> -658.99 | E39: ='Financial Inputs'!$E$23-'Financial Inputs'!$D$23 -> -631.65 | F39: =E39-D39 -> 27.34 | G39: =IF(ABS(F39)<=$C$13,"OK","INFO") -> INFO | H39: Informational: small differences can arise from items outside the cash-flow total (e.g., exchange effects, bank overdrafts). Not an error flag by itself. | I39: Informational | J39: S1/S2
A40: V26 | B40: Segment external revenue: sum of segments vs reported total (sum of absolute differences, FY2024–26) | C40: Segment Analysis | D40: =0 -> 0 | E40: =SUMPRODUCT(ABS('Segment Analysis'!B13:D13)) -> 0 | F40: =E40-D40 -> 0 | G40: =IF(ABS(F40)<=$C$13,"OK","FLAG") -> OK | H40: Reconciles. | I40: Arithmetic check passed | J40: S1/S2
A41: V27 | B41: Segment segment result: sum of segments vs reported total (sum of absolute differences, FY2024–26) | C41: Segment Analysis | D41: =0 -> 0 | E41: =SUMPRODUCT(ABS('Segment Analysis'!B23:D23)) -> 0 | F41: =E41-D41 -> 0 | G41: =IF(ABS(F41)<=$C$13,"OK","FLAG") -> OK | H41: Reconciles. | I41: Arithmetic check passed | J41: S1/S2
A42: V28 | B42: Segment segment assets: sum of segments vs reported total (sum of absolute differences, FY2024–26) | C42: Segment Analysis | D42: =0 -> 0 | E42: =SUMPRODUCT(ABS('Segment Analysis'!B33:D33)) -> 0 | F42: =E42-D42 -> 0 | G42: =IF(ABS(F42)<=$C$13,"OK","FLAG") -> OK | H42: Reconciles. | I42: Arithmetic check passed | J42: S1/S2
...

Sheet External Credit Rating
A1: External Credit Rating – CRISIL
A2: Rating rationale dated 18 September 2026. External agency opinions; NOT a lending decision. CRISIL financial indicators below are STANDALONE and are never combined with consolidated figures.
A3: Colour key: Blue = hard-coded input (as supplied) | Black = formula | Green = link to another sheet | Grey italic = not supplied / not applicable (never estimated)
A5: A. CRISIL rated instruments (rationale dated 18 September 2026)
A6: Instrument | B6: Rating | C6: Outlook | D6: Rated amount (₹ crore) | E6: Rationale date | F6: Note
A7: Non-convertible debentures (NCD) – ₹475 crore issue | B7: CRISIL AAA | C7: Stable | D7: 475 | E7: 46283 | F7: Highest long-term rating category.
A8: Non-convertible debentures (NCD) – ₹500 crore issue | B8: CRISIL AAA | C8: Stable | D8: 500 | E8: 46283 | F8: Highest long-term rating category.
A9: Commercial paper | B9: CRISIL A1+ | C9: n/a (short-term) | D9: 500 | E9: 46283 | F9: Highest short-term rating category.
A10: Short-term bank facilities | B10: CRISIL A1+ | C10: n/a (short-term) | D10: Not supplied | E10: 46283 | F10: Facility-level amount not supplied separately.
A11: Rated bank loan facilities (aggregate) | B11: Not itemised | C11: Not supplied | D11: 1087.5 | E11: 46283 | F11: Split between long-term and short-term facilities and their individual ratings were not supplied; not assumed.
A12: Per the project brief, CRISIL's action reaffirmed these ratings. Rated amounts are instrument sizes only and are not total company debt.
A14: B. What an external rating does – and does not – mean
A15: A CRISIL rating is an independent agency opinion on relative creditworthiness of a specific instrument. It is not a guarantee, a recommendation or a measure of zero risk.
A16: AAA indicates the highest degree of safety regarding timely servicing of financial obligations (CRISIL's own scale; general reference) – it still carries a small, non-zero risk of default, and ratings can be revised.
A17: Ratings assess named instruments/facilities of Mahindra & Mahindra Limited; they do not replace independent analysis of the consolidated group, including the Financial Services subsidiary.
A18: This workbook uses the ratings as an external cross-check on its own analysis; no rating, score or limit is derived from them.
A20: C. CRISIL STANDALONE indicators – DO NOT COMBINE WITH CONSOLIDATED SERIES
A21: SCOPE WARNING: These figures are standalone (Mahindra & Mahindra Limited, excluding subsidiaries such as the Financial Services business). Most other sheets are consolidated. The two scopes are not comparable and no ratio in this workbook mixes them.
A22: Metric (standalone) | B22: FY2025 | C22: FY2026 | D22: Change | E22: Unit | F22: Note
A23: Operating income | B23: 118625 | C23: 147765 | D23: =C23-B23 -> 29140 | E23: ₹ crore
A24: EBITDA | B24: 17123 | C24: 20977 | D24: =C24-B24 -> 3854 | E24: ₹ crore
A25: EBIT margin | B25: 0.111 | C25: 0.115 | D25: =C25-B25 -> 0.004 | E25: % | F25: Change shown in percentage points.
A26: PAT | B26: 11855 | C26: 15639 | D26: =C26-B26 -> 3784 | E26: ₹ crore
A27: PAT margin | B27: 0.1 | C27: 0.1058 | D27: =C27-B27 -> 0.0058 | E27: % | F27: Change shown in percentage points.
A28: Adjusted net debt / net worth | B28: NM | C28: NM | D28: n/a | E28: x | F28: Reported by CRISIL as 'NM' (not meaningful) – standalone debt is very small relative to net worth.
A29: Interest coverage | B29: 68 | C29: 84 | D29: =C29-B29 -> 16 | E29: times
A30: Standalone debt (FY2026) | B30: Not supplied | C30: 1056 | D30: n/a | E30: ₹ crore | F30: FY2025 not supplied.
A31: Estimated accrual (FY2026) | B31: Not supplied | C31: 16785 | D31: n/a | E31: ₹ crore | F31: FY2025 not supplied.
A33: D. Recalculated cross-checks on CRISIL standalone figures (formulas)
A34: Check | B34: FY2025 | C34: FY2026 | D34: Difference vs stated | E34: Unit | F34: Note
A35: EBITDA margin (EBITDA / operating income) | B35: =B24/B23 -> 0.14434563 | C35: =C24/C23 -> 0.1419619 | D35: n/a | E35: % | F35: Calculated here; not stated in the supplied indicators.
A36: PAT margin recalculated (PAT / operating income) | B36: =B26/B23 -> 0.099936776 | C36: =C26/C23 -> 0.10583697 | D36: =(C36-C27)*100 -> 0.0036970866 | E36: pp (FY26) | F36: Agrees with the stated PAT margin within rounding.
A38: E. CRISIL Q1 FY2027 standalone indicators
A39: Metric (standalone, Q1 FY2027) | B39: Value | E39: Unit | F39: Note
A40: Revenue | B40: 41959 | E40: ₹ crore | F40: Quarter (standalone).
A41: PAT | B41: 3685 | E41: ₹ crore | F41: Quarter (standalone).
A42: PAT margin – stated (approx.) | B42: 0.09 | E42: % | F42: Stated as approximately 9%.
A43: PAT margin – recalculated (PAT / revenue) | B43: =B41/B40 -> 0.087823828 | E43: % | F43: Consistent with the approximately-9% stated margin.
